Workbook

Sheet Raw OI Data
A1: NSE FAO — Raw OI Data
A2: Date | B2: Participant | C2: Fut Idx Long | D2: Fut Idx Short | E2: Fut Stk Long | F2: Fut Stk Short | G2: Opt Idx Call Long | H2: Opt Idx Put Long | I2: Opt Idx Call Short | J2: Opt Idx Put Short | K2: Opt Stk Call Long | L2: Opt Stk Put Long | M2: Opt Stk Call Short | N2: Opt Stk Put Short | O2: Total Long | P2: Total Short
A3: Jul 06 2026 | B3: Client | C3: 232341 | D3: 67709 | E3: 3179272 | F3: 234871 | G3: 2801650 | H3: 3400685 | I3: 2754218 | J3: 3913827 | K3: 1634622 | L3: 648181 | M3: 1038830 | N3: 897275 | O3: 11896752 | P3: 8906730
A4: Jul 06 2026 | B4: DII | C4: 77668 | D4: 11572 | E4: 287044 | F4: 4297008 | G4: 4195 | H4: 26015 | I4: 800 | J4: 1779 | K4: 359 | L4: 35410 | M4: 238644 | N4: 6859 | O4: 430691 | P4: 4556662
A5: Jul 06 2026 | B5: FII | C5: 32686 | D5: 273965 | E5: 3856372 | F5: 3284328 | G5: 481814 | H5: 973972 | I5: 670467 | J5: 516945 | K5: 151938 | L5: 214429 | M5: 239161 | N5: 151451 | O5: 5711211 | P5: 5136316
A6: Jul 06 2026 | B6: Pro | C6: 42645 | D6: 32094 | E6: 864025 | F6: 370506 | G6: 962571 | H6: 1246877 | I6: 824746 | J6: 1214999 | K6: 869717 | L6: 869926 | M6: 1140001 | N6: 712361 | O6: 4855761 | P6: 4294706
A7: Jul 07 2026 | B7: Client | C7: 228252 | D7: 64093 | E7: 3162432 | F7: 246922 | G7: 1803242 | H7: 1500941 | I7: 1631914 | J7: 2015837 | K7: 1779543 | L7: 675542 | M7: 1083796 | N7: 940303 | O7: 9149952 | P7: 5982864
A8: Jul 07 2026 | B8: DII | C8: 80816 | D8: 11572 | E8: 287662 | F8: 4279786 | G8: 5290 | H8: 26027 | I8: 90 | J8: 229 | K8: 434 | L8: 35491 | M8: 283816 | N8: 8721 | O8: 435720 | P8: 4584214
A9: Jul 07 2026 | B9: FII | C9: 32710 | D9: 271548 | E9: 3845780 | F9: 3242088 | G9: 355937 | H9: 718833 | I9: 544458 | J9: 275050 | K9: 164789 | L9: 235205 | M9: 259677 | N9: 162062 | O9: 5353254 | P9: 4754883
A10: Jul 07 2026 | B10: Pro | C10: 38805 | D10: 33370 | E10: 867367 | F10: 394445 | G10: 583538 | H10: 632342 | I10: 571546 | J10: 587027 | K10: 909534 | L10: 922116 | M10: 1227011 | N10: 757268 | O10: 3953702 | P10: 3570667
A11: Jul 08 2026 | B11: Client | C11: 245471 | D11: 58316 | E11: 3095220 | F11: 233127 | G11: 2773248 | H11: 1722410 | I11: 2479076 | J11: 2351332 | K11: 1858115 | L11: 613580 | M11: 1084323 | N11: 967950 | O11: 10308044 | P11: 7174124
A12: Jul 08 2026 | B12: DII | C12: 79832 | D12: 8602 | E12: 298456 | F12: 4219367 | G12: 6745 | H12: 28169 | I12: 940 | J12: 369 | K12: 523 | L12: 35450 | M12: 303692 | N12: 9169 | O12: 449175 | P12: 4542139
A13: Jul 08 2026 | B13: FII | C13: 30225 | D13: 298811 | E13: 3804278 | F13: 3226723 | G13: 486150 | H13: 912286 | I13: 769301 | J13: 365622 | K13: 180386 | L13: 280738 | M13: 293100 | N13: 169283 | O13: 5694063 | P13: 5122840
A14: Jul 08 2026 | B14: Pro | C14: 46256 | D14: 36055 | E14: 888725 | F14: 407462 | G14: 920746 | H14: 744822 | I14: 937573 | J14: 690364 | K14: 934059 | L14: 997230 | M14: 1291968 | N14: 780596 | O14: 4531838 | P14: 4144018
... A22: Jul 10 2026 | B22: Pro | C22: 51172 | D22: 33516 | E22: 903186 | F22: 447680 | G22: 973913 | H22: 1201939 | I22: 798997 | J22: 1079415 | K22: 1037959 | L22: 1031050 | M22: 1384141 | N22: 879567 | O22: 5199219 | P22: 4623316

Sheet Raw TV Data
A1: NSE FAO — Raw TV Data
A2: Date | B2: Participant | C2: Fut Idx Long | D2: Fut Idx Short | E2: Fut Stk Long | F2: Fut Stk Short | G2: Opt Idx Call Long | H2: Opt Idx Put Long | I2: Opt Idx Call Short | J2: Opt Idx Put Short | K2: Opt Stk Call Long | L2: Opt Stk Put Long | M2: Opt Stk Call Short | N2: Opt Stk Put Short | O2: Total Long | P2: Total Short
A3: Jul 06 2026 | B3: Client | C3: 35762 | D3: 43827 | E3: 275406 | F3: 308498 | G3: 26676122 | H3: 23340629 | I3: 26717715 | J3: 23240950 | K3: 1161255 | L3: 417475 | M3: 1138509 | N3: 399372 | O3: 51906649 | P3: 51848871
A4: Jul 06 2026 | B4: DII | C4: 1760 | D4: 238 | E4: 83827 | F4: 58976 | G4: 195 | H4: 1074 | I4: 55 | J4: 1879 | K4: 262 | L4: 921 | M4: 37331 | N4: 891 | O4: 88039 | P4: 99370
A5: Jul 06 2026 | B5: FII | C5: 17088 | D5: 7600 | E5: 249999 | F5: 225304 | G5: 3473359 | H5: 3702980 | I5: 3428539 | J5: 3723128 | K5: 186781 | L5: 110242 | M5: 193558 | N5: 112409 | O5: 7740449 | P5: 7690538
A6: Jul 06 2026 | B6: Pro | C6: 13446 | D6: 16391 | E6: 325838 | F6: 342292 | G6: 35248941 | H6: 34721560 | I6: 35252308 | J6: 34800286 | K6: 1982791 | L6: 1039069 | M6: 1961691 | N6: 1055035 | O6: 73331645 | P6: 73428003
A7: Jul 07 2026 | B7: Client | C7: 44003 | D7: 44476 | E7: 300539 | F7: 329430 | G7: 67402038 | H7: 70517568 | I7: 67225117 | J7: 71052698 | K7: 1267969 | L7: 473259 | M7: 1168014 | N7: 488926 | O7: 140005376 | P7: 140308661
A8: Jul 07 2026 | B8: DII | C8: 3193 | D8: 45 | E8: 105193 | F8: 87353 | G8: 1170 | H8: 2483 | I8: 165 | J8: 1721 | K8: 484 | L8: 424 | M8: 45581 | N8: 2205 | O8: 112947 | P8: 137070
A9: Jul 07 2026 | B9: FII | C9: 10046 | D9: 7605 | E9: 328521 | F9: 296873 | G9: 8184095 | H9: 9730830 | I9: 8561132 | J9: 9608221 | K9: 226994 | L9: 137836 | M9: 234659 | N9: 127671 | O9: 18618322 | P9: 18836161
A10: Jul 07 2026 | B10: Pro | C10: 15625 | D10: 20741 | E10: 370719 | F10: 391316 | G10: 107696779 | H10: 125162220 | I10: 107497668 | J10: 124750461 | K10: 2218474 | L10: 1300942 | M10: 2265667 | N10: 1293659 | O10: 236764759 | P10: 236219512
A11: Jul 08 2026 | B11: Client | C11: 108342 | D11: 85346 | E11: 376370 | F11: 429787 | G11: 13086884 | H11: 15396600 | I11: 12964040 | J11: 15510626 | K11: 1406004 | L11: 662761 | M11: 1327959 | N11: 752370 | O11: 31036961 | P11: 31070128
A12: Jul 08 2026 | B12: DII | C12: 8194 | D12: 6208 | E12: 198232 | F12: 127019 | G12: 1655 | H12: 7900 | I12: 1050 | J12: 5898 | K12: 6019 | L12: 311 | M12: 25806 | N12: 800 | O12: 222311 | P12: 166781
A13: Jul 08 2026 | B13: FII | C13: 15891 | D13: 45639 | E13: 415974 | F13: 442111 | G13: 2694308 | H13: 3045543 | I13: 2788938 | J13: 2942662 | K13: 327398 | L13: 222865 | M13: 345224 | N13: 184553 | O13: 6721979 | P13: 6749127
A14: Jul 08 2026 | B14: Pro | C14: 53075 | D14: 48309 | E14: 514091 | F14: 505750 | G14: 17843951 | H14: 18795655 | I14: 17872770 | J14: 18786512 | K14: 2631306 | L14: 1818181 | M14: 2671738 | N14: 1766395 | O14: 41656259 | P14: 41651474
... A22: Jul 10 2026 | B22: Pro | C22: 18097 | D22: 17395 | E22: 378884 | F22: 398649 | G22: 23059141 | H22: 21952478 | I22: 22962378 | J22: 21923008 | K22: 2592408 | L22: 1384626 | M22: 2570403 | N22: 1408216 | O22: 49385634 | P22: 49280049

Sheet Raw Chain Data
A1: NSE FAO — Raw Option Chain Data
C2: CALLS | J2: PUTS
A3: Date | B3: Strike | C3: Call OI | D3: Call ΔOI | E3: Call Vol | F3: Call IV | G3: Call LTP | H3: Call Chng | I3: Put OI | J3: Put ΔOI | K3: Put Vol | L3: Put IV | M3: Put LTP | N3: Put Chng
A4: Jul 10 2026
A5: Jul 10 2026 | B5: 21400 | C5: 4 | D5: 0 | E5: 3 | G5: 2820 | H5: 106.2 | I5: 44925 | J5: 5835 | K5: 46894 | L5: 42.32 | M5: 0.75 | N5: -0.15
A6: Jul 10 2026 | B6: 21450 | C6: 32 | D6: -1 | E6: 16 | G6: 2759.2 | H6: 112.6 | I6: 1722 | J6: 724 | K6: 6870 | L6: 42.34 | M6: 0.9 | N6: -0.05
A7: Jul 10 2026 | B7: 21500 | C7: 36 | D7: -1 | E7: 2 | G7: 2673.4 | H7: 144.7 | I7: 31422 | J7: 1102 | K7: 85224 | L7: 41.38 | M7: 0.85 | N7: -0.1
A8: Jul 10 2026 | B8: 21550 | C8: 31 | D8: -7 | E8: 19 | G8: 2660.9 | H8: 211.85 | I8: 1482 | J8: 603 | K8: 4879 | L8: 40.65 | M8: 0.85 | N8: -0.1
A9: Jul 10 2026 | B9: 21600 | C9: 15 | D9: -11 | E9: 11 | G9: 2610.35 | H9: 150 | I9: 5526 | J9: 1391 | K9: 29596 | L9: 40.36 | M9: 0.95 | N9: -0.1
A10: Jul 10 2026 | B10: 21650 | C10: 46 | D10: -1 | E10: 19 | G10: 2565.25 | H10: 157.6 | I10: 1296 | J10: 605 | K10: 4521 | L10: 39.63 | M10: 0.95 | N10: -0.05
A11: Jul 10 2026 | B11: 21700 | C11: 61 | D11: -6 | E11: 16 | G11: 2509.05 | H11: 256.45 | I11: 5187 | J11: 2837 | K11: 42257 | L11: 39.1 | M11: 1
A12: Jul 10 2026 | B12: 21750 | C12: 30 | D12: -12 | E12: 14 | G12: 2410 | H12: 173.4 | I12: 992 | J12: 391 | K12: 2857 | L12: 38.55 | M12: 1.05 | N12: -0.05
A13: Jul 10 2026 | B13: 21800 | C13: 6 | D13: 0 | E13: 0 | G13: 2139.8 | I13: 13563 | J13: 2662 | K13: 63202 | L13: 37.81 | M13: 1.05
A14: Jul 10 2026 | B14: 21850 | C14: 7 | D14: -6 | E14: 6 | G14: 2354.25 | H14: 199 | I14: 1653 | J14: 803 | K14: 8576 | L14: 37.07 | M14: 1.05 | N14: -0.2
A15: Jul 10 2026 | B15: 21900 | C15: 16 | D15: 0 | E15: 0 | F15: 52.41 | G15: 2112.05 | I15: 5124 | J15: 2149 | K15: 23336 | L15: 36.68 | M15: 1.15 | N15: -0.15
A16: Jul 10 2026 | B16: 21950 | C16: 50 | D16: 0 | E16: 5 | G16: 2231.85 | H16: 196.3 | I16: 1751 | J16: 569 | K16: 14101 | L16: 36.1 | M16: 1.2 | N16: -0.15
A17: Jul 10 2026 | B17: 22000 | C17: 50 | D17: -1 | E17: 3 | G17: 2219.3 | H17: 293.6 | I17: 65388 | J17: 7740 | K17: 189567 | L17: 35.66 | M17: 1.3 | N17: -0.15
A18: Jul 10 2026 | B18: 22050 | C18: 25 | D18: -17 | E18: 17 | G18: 2159 | H18: 274.2 | I18: 3066 | J18: 472 | K18: 21583 | L18: 35.05 | M18: 1.35 | N18: -0.15
A19: Jul 10 2026 | B19: 22100 | C19: 52 | D19: 0 | E19: 4 | G19: 2090.9 | H19: 231.25 | I19: 7998 | J19: 3754 | K19: 43806 | L19: 33.71 | M19: 1.15 | N19: -0.4
A20: Jul 10 2026 | B20: 22150 | C20: 25 | D20: -7 | E20: 21 | G20: 2058.95 | H20: 198.05 | I20: 2092 | J20: 442 | K20: 26880 | L20: 33.54 | M20: 1.35 | N20: -0.35
A21: Jul 10 2026 | B21: 22200 | C21: 29 | D21: -2 | E21: 12 | G21: 2011.9 | H21: 229.3 | I21: 20160 | J21: 6194 | K21: 102632 | L21: 32.79 | M21: 1.35 | N21: -0.4
A22: Jul 10 2026 | B22: 22250 | C22: 8 | D22: 5 | E22: 11 | G22: 1955.9 | H22: 207.6 | I22: 2824 | J22: 136 | K22: 25041 | L22: 32.17 | M22: 1.4 | N22: -0.45
A23: Jul 10 2026 | B23: 22300 | C23: 15 | D23: -4 | E23: 6 | F23: 47.99 | G23: 1955.1 | H23: 173 | I23: 20565 | J23: 10157 | K23: 113900 | L23: 31.54 | M23: 1.45 | N23: -0.45
A24: Jul 10 2026 | B24: 22350 | C24: 32 | D24: -14 | E24: 14 | G24: 1861.45 | H24: 176.45 | I24: 2896 | J24: -98 | K24: 26184 | L24: 30.9 | M24: 1.5 | N24: -0.5
A25: Jul 10 2026 | B25: 22400 | C25: 32 | D25: -8 | E25: 12 | G25: 1811.5 | H25: 146.75 | I25: 12982 | J25: 919 | K25: 108673 | L25: 30.14 | M25: 1.5 | N25: -0.65
A26: Jul 10 2026 | B26: 22450 | C26: 18 | D26: 0 | E26: 1 | G26: 1723.45 | H26: 188.85 | I26: 5141 | J26: 2972 | K26: 40753 | L26: 29.6 | M26: 1.6 | N26: -0.75
A27: Jul 10 2026 | B27: 22500 | C27: 182 | D27: -2 | E27: 29 | G27: 1717.35 | H27: 267.6 | I27: 108674 | J27: 13919 | K27: 550357 | L27: 28.61 | M27: 1.5 | N27: -0.95
A28: Jul 10 2026 | B28: 22550 | C28: 34 | D28: -7 | E28: 13 | G28: 1609.05 | H28: 179.3 | I28: 9829 | J28: 2705 | K28: 78551 | L28: 27.85 | M28: 1.5 | N28: -1.05
A29: Jul 10 2026 | B29: 22600 | C29: 37 | D29: -1 | E29: 3 | G29: 1606.25 | H29: 122.3 | I29: 31813 | J29: 131 | K29: 204077 | L29: 27.4 | M29: 1.65 | N29: -1.05
A30: Jul 10 2026 | B30: 22650 | C30: 33 | D30: 0 | E30: 0 | F30: 51.33 | G30: 1428.85 | I30: 7232 | J30: 966 | K30: 75440 | L30: 27 | M30: 1.85 | N30: -1
A31: Jul 10 2026 | B31: 22700 | C31: 36 | D31: 7 | E31: 18 | G31: 1509.95 | H31: 278.45 | I31: 46616 | J31: 19090 | K31: 267087 | L31: 26.04 | M31: 1.75 | N31: -1.2
A32: Jul 10 2026 | B32: 22750 | C32: 45 | D32: 0 | E32: 1 | G32: 1424.35 | H32: 196.2 | I32: 10081 | J32: 1264 | K32: 75937 | L32: 25.44 | M32: 1.85 | N32: -1.3
A33: Jul 10 2026 | B33: 22800 | C33: 96 | D33: 9 | E33: 9 | G33: 1407 | H33: 162 | I33: 59723 | J33: 19176 | K33: 448162 | L33: 25.06 | M33: 2.1 | N33: -1.35
A34: Jul 10 2026 | B34: 22850 | C34: 67 | D34: -8 | E34: 25 | G34: 1338.15 | H34: 232.25 | I34: 9153 | J34: 2488 | K34: 85113 | L34: 24.49 | M34: 2.25 | N34: -1.65
A35: Jul 10 2026 | B35: 22900 | C35: 24 | D35: 1 | E35: 10 | G35: 1305.4 | H35: 239.2 | I35: 34578 | J35: 11301 | K35: 324879 | L35: 23.69 | M35: 2.25 | N35: -1.9
A36: Jul 10 2026 | B36: 22950 | C36: 91 | D36: -9 | E36: 12 | G36: 1252.55 | H36: 245 | I36: 9859 | J36: 348 | K36: 111977 | L36: 22.96 | M36: 2.3 | N36: -2.25
A37: Jul 10 2026 | B37: 23000 | C37: 1495 | D37: -54 | E37: 655 | G37: 1215.85 | H37: 251.35 | I37: 188373 | J37: 61076 | K37: 1006753 | L37: 22.34 | M37: 2.45 | N37: -2.65
A38: Jul 10 2026 | B38: 23050 | C38: 54 | D38: -1 | E38: 8 | G38: 1140.25 | H38: 255.6 | I38: 12463 | J38: -1268 | K38: 138654 | L38: 21.59 | M38: 2.5 | N38: -3.1
A39: Jul 10 2026 | B39: 23100 | C39: 130 | D39: 30 | E39: 172 | G39: 1116.6 | H39: 258.9 | I39: 42054 | J39: 11449 | K39: 425825 | L39: 21.01 | M39: 2.7 | N39: -3.35
A40: Jul 10 2026 | B40: 23150 | C40: 47 | D40: 24 | E40: 29 | G40: 1030.65 | H40: 236 | I40: 13673 | J40: 1002 | K40: 203593 | L40: 20.39 | M40: 2.9 | N40: -3.9
...

Sheet OI Dashboard
A1: NSE FAO — OI Dashboard
A2: Metric | B2: Jul 06 2026 | G2: Jul 07 2026 | L2: Jul 08 2026 | Q2: Jul 09 2026 | V2: Jul 10 2026
B3: Client | C3: DII | D3: FII | E3: Pro | G3: Client | H3: DII | I3: FII | J3: Pro | L3: Client | M3: DII | N3: FII | O3: Pro | Q3: Client | R3: DII | S3: FII | T3: Pro | V3: Client | W3: DII | X3: FII | Y3: Pro
A4: FUTURES — INDEX
A5: Long OI | B5: ='Raw OI Data'!C3 | C5: ='Raw OI Data'!C4 | D5: ='Raw OI Data'!C5 | E5: ='Raw OI Data'!C6 | G5: ='Raw OI Data'!C7 | H5: ='Raw OI Data'!C8 | I5: ='Raw OI Data'!C9 | J5: ='Raw OI Data'!C10 | L5: ='Raw OI Data'!C11 | M5: ='Raw OI Data'!C12 | N5: ='Raw OI Data'!C13 | O5: ='Raw OI Data'!C14 | Q5: ='Raw OI Data'!C15 | R5: ='Raw OI Data'!C16 | S5: ='Raw OI Data'!C17 | T5: ='Raw OI Data'!C18 | V5: ='Raw OI Data'!C19 | W5: ='Raw OI Data'!C20 | X5: ='Raw OI Data'!C21 | Y5: ='Raw OI Data'!C22
A6: Short OI | B6: ='Raw OI Data'!D3 | C6: ='Raw OI Data'!D4 | D6: ='Raw OI Data'!D5 | E6: ='Raw OI Data'!D6 | G6: ='Raw OI Data'!D7 | H6: ='Raw OI Data'!D8 | I6: ='Raw OI Data'!D9 | J6: ='Raw OI Data'!D10 | L6: ='Raw OI Data'!D11 | M6: ='Raw OI Data'!D12 | N6: ='Raw OI Data'!D13 | O6: ='Raw OI Data'!D14 | Q6: ='Raw OI Data'!D15 | R6: ='Raw OI Data'!D16 | S6: ='Raw OI Data'!D17 | T6: ='Raw OI Data'!D18 | V6: ='Raw OI Data'!D19 | W6: ='Raw OI Data'!D20 | X6: ='Raw OI Data'!D21 | Y6: ='Raw OI Data'!D22
A7: Net OI (L−S) | B7: ='Raw OI Data'!C3-'Raw OI Data'!D3 | C7: ='Raw OI Data'!C4-'Raw OI Data'!D4 | D7: ='Raw OI Data'!C5-'Raw OI Data'!D5 | E7: ='Raw OI Data'!C6-'Raw OI Data'!D6 | G7: ='Raw OI Data'!C7-'Raw OI Data'!D7 | H7: ='Raw OI Data'!C8-'Raw OI Data'!D8 | I7: ='Raw OI Data'!C9-'Raw OI Data'!D9 | J7: ='Raw OI Data'!C10-'Raw OI Data'!D10 | L7: ='Raw OI Data'!C11-'Raw OI Data'!D11 | M7: ='Raw OI Data'!C12-'Raw OI Data'!D12 | N7: ='Raw OI Data'!C13-'Raw OI Data'!D13 | O7: ='Raw OI Data'!C14-'Raw OI Data'!D14 | Q7: ='Raw OI Data'!C15-'Raw OI Data'!D15 | R7: ='Raw OI Data'!C16-'Raw OI Data'!D16 | S7: ='Raw OI Data'!C17-'Raw OI Data'!D17 | T7: ='Raw OI Data'!C18-'Raw OI Data'!D18 | V7: ='Raw OI Data'!C19-'Raw OI Data'!D19 | W7: ='Raw OI Data'!C20-'Raw OI Data'!D20 | X7: ='Raw OI Data'!C21-'Raw OI Data'!D21 | Y7: ='Raw OI Data'!C22-'Raw OI Data'!D22
A8: L/S Ratio | B8: =IFERROR('Raw OI Data'!C3/'Raw OI Data'!D3,0) | C8: =IFERROR('Raw OI Data'!C4/'Raw OI Data'!D4,0) | D8: =IFERROR('Raw OI Data'!C5/'Raw OI Data'!D5,0) | E8: =IFERROR('Raw OI Data'!C6/'Raw OI Data'!D6,0) | G8: =IFERROR('Raw OI Data'!C7/'Raw OI Data'!D7,0) | H8: =IFERROR('Raw OI Data'!C8/'Raw OI Data'!D8,0) | I8: =IFERROR('Raw OI Data'!C9/'Raw OI Data'!D9,0) | J8: =IFERROR('Raw OI Data'!C10/'Raw OI Data'!D10,0) | L8: =IFERROR('Raw OI Data'!C11/'Raw OI Data'!D11,0) | M8: =IFERROR('Raw OI Data'!C12/'Raw OI Data'!D12,0) | N8: =IFERROR('Raw OI Data'!C13/'Raw OI Data'!D13,0) | O8: =IFERROR('Raw OI Data'!C14/'Raw OI Data'!D14,0) | Q8: =IFERROR('Raw OI Data'!C15/'Raw OI Data'!D15,0) | R8: =IFERROR('Raw OI Data'!C16/'Raw OI Data'!D16,0) | S8: =IFERROR('Raw OI Data'!C17/'Raw OI Data'!D17,0) | T8: =IFERROR('Raw OI Data'!C18/'Raw OI Data'!D18,0) | V8: =IFERROR('Raw OI Data'!C19/'Raw OI Data'!D19,0) | W8: =IFERROR('Raw OI Data'!C20/'Raw OI Data'!D20,0) | X8: =IFERROR('Raw OI Data'!C21/'Raw OI Data'!D21,0) | Y8: =IFERROR('Raw OI Data'!C22/'Raw OI Data'!D22,0)
A9: FUTURES — STOCK
A10: Long OI | B10: ='Raw OI Data'!E3 | C10: ='Raw OI Data'!E4 | D10: ='Raw OI Data'!E5 | E10: ='Raw OI Data'!E6 | G10: ='Raw OI Data'!E7 | H10: ='Raw OI Data'!E8 | I10: ='Raw OI Data'!E9 | J10: ='Raw OI Data'!E10 | L10: ='Raw OI Data'!E11 | M10: ='Raw OI Data'!E12 | N10: ='Raw OI Data'!E13 | O10: ='Raw OI Data'!E14 | Q10: ='Raw OI Data'!E15 | R10: ='Raw OI Data'!E16 | S10: ='Raw OI Data'!E17 | T10: ='Raw OI Data'!E18 | V10: ='Raw OI Data'!E19 | W10: ='Raw OI Data'!E20 | X10: ='Raw OI Data'!E21 | Y10: ='Raw OI Data'!E22
A11: Short OI | B11: ='Raw OI Data'!F3 | C11: ='Raw OI Data'!F4 | D11: ='Raw OI Data'!F5 | E11: ='Raw OI Data'!F6 | G11: ='Raw OI Data'!F7 | H11: ='Raw OI Data'!F8 | I11: ='Raw OI Data'!F9 | J11: ='Raw OI Data'!F10 | L11: ='Raw OI Data'!F11 | M11: ='Raw OI Data'!F12 | N11: ='Raw OI Data'!F13 | O11: ='Raw OI Data'!F14 | Q11: ='Raw OI Data'!F15 | R11: ='Raw OI Data'!F16 | S11: ='Raw OI Data'!F17 | T11: ='Raw OI Data'!F18 | V11: ='Raw OI Data'!F19 | W11: ='Raw OI Data'!F20 | X11: ='Raw OI Data'!F21 | Y11: ='Raw OI Data'!F22
A12: Net OI (L−S) | B12: ='Raw OI Data'!E3-'Raw OI Data'!F3 | C12: ='Raw OI Data'!E4-'Raw OI Data'!F4 | D12: ='Raw OI Data'!E5-'Raw OI Data'!F5 | E12: ='Raw OI Data'!E6-'Raw OI Data'!F6 | G12: ='Raw OI Data'!E7-'Raw OI Data'!F7 | H12: ='Raw OI Data'!E8-'Raw OI Data'!F8 | I12: ='Raw OI Data'!E9-'Raw OI Data'!F9 | J12: ='Raw OI Data'!E10-'Raw OI Data'!F10 | L12: ='Raw OI Data'!E11-'Raw OI Data'!F11 | M12: ='Raw OI Data'!E12-'Raw OI Data'!F12 | N12: ='Raw OI Data'!E13-'Raw OI Data'!F13 | O12: ='Raw OI Data'!E14-'Raw OI Data'!F14 | Q12: ='Raw OI Data'!E15-'Raw OI Data'!F15 | R12: ='Raw OI Data'!E16-'Raw OI Data'!F16 | S12: ='Raw OI Data'!E17-'Raw OI Data'!F17 | T12: ='Raw OI Data'!E18-'Raw OI Data'!F18 | V12: ='Raw OI Data'!E19-'Raw OI Data'!F19 | W12: ='Raw OI Data'!E20-'Raw OI Data'!F20 | X12: ='Raw OI Data'!E21-'Raw OI Data'!F21 | Y12: ='Raw OI Data'!E22-'Raw OI Data'!F22
A13: L/S Ratio | B13: =IFERROR('Raw OI Data'!E3/'Raw OI Data'!F3,0) | C13: =IFERROR('Raw OI Data'!E4/'Raw OI Data'!F4,0) | D13: =IFERROR('Raw OI Data'!E5/'Raw OI Data'!F5,0) | E13: =IFERROR('Raw OI Data'!E6/'Raw OI Data'!F6,0) | G13: =IFERROR('Raw OI Data'!E7/'Raw OI Data'!F7,0) | H13: =IFERROR('Raw OI Data'!E8/'Raw OI Data'!F8,0) | I13: =IFERROR('Raw OI Data'!E9/'Raw OI Data'!F9,0) | J13: =IFERROR('Raw OI Data'!E10/'Raw OI Data'!F10,0) | L13: =IFERROR('Raw OI Data'!E11/'Raw OI Data'!F11,0) | M13: =IFERROR('Raw OI Data'!E12/'Raw OI Data'!F12,0) | N13: =IFERROR('Raw OI Data'!E13/'Raw OI Data'!F13,0) | O13: =IFERROR('Raw OI Data'!E14/'Raw OI Data'!F14,0) | Q13: =IFERROR('Raw OI Data'!E15/'Raw OI Data'!F15,0) | R13: =IFERROR('Raw OI Data'!E16/'Raw OI Data'!F16,0) | S13: =IFERROR('Raw OI Data'!E17/'Raw OI Data'!F17,0) | T13: =IFERROR('Raw OI Data'!E18/'Raw OI Data'!F18,0) | V13: =IFERROR('Raw OI Data'!E19/'Raw OI Data'!F19,0) | W13: =IFERROR('Raw OI Data'!E20/'Raw OI Data'!F20,0) | X13: =IFERROR('Raw OI Data'!E21/'Raw OI Data'!F21,0) | Y13: =IFERROR('Raw OI Data'!E22/'Raw OI Data'!F22,0)
A14: OPTIONS — INDEX CALLS
A15: Call Long OI | B15: ='Raw OI Data'!G3 | C15: ='Raw OI Data'!G4 | D15: ='Raw OI Data'!G5 | E15: ='Raw OI Data'!G6 | G15: ='Raw OI Data'!G7 | H15: ='Raw OI Data'!G8 | I15: ='Raw OI Data'!G9 | J15: ='Raw OI Data'!G10 | L15: ='Raw OI Data'!G11 | M15: ='Raw OI Data'!G12 | N15: ='Raw OI Data'!G13 | O15: ='Raw OI Data'!G14 | Q15: ='Raw OI Data'!G15 | R15: ='Raw OI Data'!G16 | S15: ='Raw OI Data'!G17 | T15: ='Raw OI Data'!G18 | V15: ='Raw OI Data'!G19 | W15: ='Raw OI Data'!G20 | X15: ='Raw OI Data'!G21 | Y15: ='Raw OI Data'!G22
A16: Call Short OI | B16: ='Raw OI Data'!I3 | C16: ='Raw OI Data'!I4 | D16: ='Raw OI Data'!I5 | E16: ='Raw OI Data'!I6 | G16: ='Raw OI Data'!I7 | H16: ='Raw OI Data'!I8 | I16: ='Raw OI Data'!I9 | J16: ='Raw OI Data'!I10 | L16: ='Raw OI Data'!I11 | M16: ='Raw OI Data'!I12 | N16: ='Raw OI Data'!I13 | O16: ='Raw OI Data'!I14 | Q16: ='Raw OI Data'!I15 | R16: ='Raw OI Data'!I16 | S16: ='Raw OI Data'!I17 | T16: ='Raw OI Data'!I18 | V16: ='Raw OI Data'!I19 | W16: ='Raw OI Data'!I20 | X16: ='Raw OI Data'!I21 | Y16: ='Raw OI Data'!I22
A17: Net Call OI | B17: ='Raw OI Data'!G3-'Raw OI Data'!I3 | C17: ='Raw OI Data'!G4-'Raw OI Data'!I4 | D17: ='Raw OI Data'!G5-'Raw OI Data'!I5 | E17: ='Raw OI Data'!G6-'Raw OI Data'!I6 | G17: ='Raw OI Data'!G7-'Raw OI Data'!I7 | H17: ='Raw OI Data'!G8-'Raw OI Data'!I8 | I17: ='Raw OI Data'!G9-'Raw OI Data'!I9 | J17: ='Raw OI Data'!G10-'Raw OI Data'!I10 | L17: ='Raw OI Data'!G11-'Raw OI Data'!I11 | M17: ='Raw OI Data'!G12-'Raw OI Data'!I12 | N17: ='Raw OI Data'!G13-'Raw OI Data'!I13 | O17: ='Raw OI Data'!G14-'Raw OI Data'!I14 | Q17: ='Raw OI Data'!G15-'Raw OI Data'!I15 | R17: ='Raw OI Data'!G16-'Raw OI Data'!I16 | S17: ='Raw OI Data'!G17-'Raw OI Data'!I17 | T17: ='Raw OI Data'!G18-'Raw OI Data'!I18 | V17: ='Raw OI Data'!G19-'Raw OI Data'!I19 | W17: ='Raw OI Data'!G20-'Raw OI Data'!I20 | X17: ='Raw OI Data'!G21-'Raw OI Data'!I21 | Y17: ='Raw OI Data'!G22-'Raw OI Data'!I22
A18: OPTIONS — INDEX PUTS
A19: Put Long OI | B19: ='Raw OI Data'!H3 | C19: ='Raw OI Data'!H4 | D19: ='Raw OI Data'!H5 | E19: ='Raw OI Data'!H6 | G19: ='Raw OI Data'!H7 | H19: ='Raw OI Data'!H8 | I19: ='Raw OI Data'!H9 | J19: ='Raw OI Data'!H10 | L19: ='Raw OI Data'!H11 | M19: ='Raw OI Data'!H12 | N19: ='Raw OI Data'!H13 | O19: ='Raw OI Data'!H14 | Q19: ='Raw OI Data'!H15 | R19: ='Raw OI Data'!H16 | S19: ='Raw OI Data'!H17 | T19: ='Raw OI Data'!H18 | V19: ='Raw OI Data'!H19 | W19: ='Raw OI Data'!H20 | X19: ='Raw OI Data'!H21 | Y19: ='Raw OI Data'!H22
A20: Put Short OI | B20: ='Raw OI Data'!J3 | C20: ='Raw OI Data'!J4 | D20: ='Raw OI Data'!J5 | E20: ='Raw OI Data'!J6 | G20: ='Raw OI Data'!J7 | H20: ='Raw OI Data'!J8 | I20: ='Raw OI Data'!J9 | J20: ='Raw OI Data'!J10 | L20: ='Raw OI Data'!J11 | M20: ='Raw OI Data'!J12 | N20: ='Raw OI Data'!J13 | O20: ='Raw OI Data'!J14 | Q20: ='Raw OI Data'!J15 | R20: ='Raw OI Data'!J16 | S20: ='Raw OI Data'!J17 | T20: ='Raw OI Data'!J18 | V20: ='Raw OI Data'!J19 | W20: ='Raw OI Data'!J20 | X20: ='Raw OI Data'!J21 | Y20: ='Raw OI Data'!J22
A21: Net Put OI | B21: ='Raw OI Data'!H3-'Raw OI Data'!J3 | C21: ='Raw OI Data'!H4-'Raw OI Data'!J4 | D21: ='Raw OI Data'!H5-'Raw OI Data'!J5 | E21: ='Raw OI Data'!H6-'Raw OI Data'!J6 | G21: ='Raw OI Data'!H7-'Raw OI Data'!J7 | H21: ='Raw OI Data'!H8-'Raw OI Data'!J8 | I21: ='Raw OI Data'!H9-'Raw OI Data'!J9 | J21: ='Raw OI Data'!H10-'Raw OI Data'!J10 | L21: ='Raw OI Data'!H11-'Raw OI Data'!J11 | M21: ='Raw OI Data'!H12-'Raw OI Data'!J12 | N21: ='Raw OI Data'!H13-'Raw OI Data'!J13 | O21: ='Raw OI Data'!H14-'Raw OI Data'!J14 | Q21: ='Raw OI Data'!H15-'Raw OI Data'!J15 | R21: ='Raw OI Data'!H16-'Raw OI Data'!J16 | S21: ='Raw OI Data'!H17-'Raw OI Data'!J17 | T21: ='Raw OI Data'!H18-'Raw OI Data'!J18 | V21: ='Raw OI Data'!H19-'Raw OI Data'!J19 | W21: ='Raw OI Data'!H20-'Raw OI Data'!J20 | X21: ='Raw OI Data'!H21-'Raw OI Data'!J21 | Y21: ='Raw OI Data'!H22-'Raw OI Data'!J22
A22: OPTIONS — STOCK CALLS
A23: Call Long OI | B23: ='Raw OI Data'!K3 | C23: ='Raw OI Data'!K4 | D23: ='Raw OI Data'!K5 | E23: ='Raw OI Data'!K6 | G23: ='Raw OI Data'!K7 | H23: ='Raw OI Data'!K8 | I23: ='Raw OI Data'!K9 | J23: ='Raw OI Data'!K10 | L23: ='Raw OI Data'!K11 | M23: ='Raw OI Data'!K12 | N23: ='Raw OI Data'!K13 | O23: ='Raw OI Data'!K14 | Q23: ='Raw OI Data'!K15 | R23: ='Raw OI Data'!K16 | S23: ='Raw OI Data'!K17 | T23: ='Raw OI Data'!K18 | V23: ='Raw OI Data'!K19 | W23: ='Raw OI Data'!K20 | X23: ='Raw OI Data'!K21 | Y23: ='Raw OI Data'!K22
A24: Call Short OI | B24: ='Raw OI Data'!M3 | C24: ='Raw OI Data'!M4 | D24: ='Raw OI Data'!M5 | E24: ='Raw OI Data'!M6 | G24: ='Raw OI Data'!M7 | H24: ='Raw OI Data'!M8 | I24: ='Raw OI Data'!M9 | J24: ='Raw OI Data'!M10 | L24: ='Raw OI Data'!M11 | M24: ='Raw OI Data'!M12 | N24: ='Raw OI Data'!M13 | O24: ='Raw OI Data'!M14 | Q24: ='Raw OI Data'!M15 | R24: ='Raw OI Data'!M16 | S24: ='Raw OI Data'!M17 | T24: ='Raw OI Data'!M18 | V24: ='Raw OI Data'!M19 | W24: ='Raw OI Data'!M20 | X24: ='Raw OI Data'!M21 | Y24: ='Raw OI Data'!M22
A25: Net Call OI | B25: ='Raw OI Data'!K3-'Raw OI Data'!M3 | C25: ='Raw OI Data'!K4-'Raw OI Data'!M4 | D25: ='Raw OI Data'!K5-'Raw OI Data'!M5 | E25: ='Raw OI Data'!K6-'Raw OI Data'!M6 | G25: ='Raw OI Data'!K7-'Raw OI Data'!M7 | H25: ='Raw OI Data'!K8-'Raw OI Data'!M8 | I25: ='Raw OI Data'!K9-'Raw OI Data'!M9 | J25: ='Raw OI Data'!K10-'Raw OI Data'!M10 | L25: ='Raw OI Data'!K11-'Raw OI Data'!M11 | M25: ='Raw OI Data'!K12-'Raw OI Data'!M12 | N25: ='Raw OI Data'!K13-'Raw OI Data'!M13 | O25: ='Raw OI Data'!K14-'Raw OI Data'!M14 | Q25: ='Raw OI Data'!K15-'Raw OI Data'!M15 | R25: ='Raw OI Data'!K16-'Raw OI Data'!M16 | S25: ='Raw OI Data'!K17-'Raw OI Data'!M17 | T25: ='Raw OI Data'!K18-'Raw OI Data'!M18 | V25: ='Raw OI Data'!K19-'Raw OI Data'!M19 | W25: ='Raw OI Data'!K20-'Raw OI Data'!M20 | X25: ='Raw OI Data'!K21-'Raw OI Data'!M21 | Y25: ='Raw OI Data'!K22-'Raw OI Data'!M22
A26: OPTIONS — STOCK PUTS
A27: Put Long OI | B27: ='Raw OI Data'!L3 | C27: ='Raw OI Data'!L4 | D27: ='Raw OI Data'!L5 | E27: ='Raw OI Data'!L6 | G27: ='Raw OI Data'!L7 | H27: ='Raw OI Data'!L8 | I27: ='Raw OI Data'!L9 | J27: ='Raw OI Data'!L10 | L27: ='Raw OI Data'!L11 | M27: ='Raw OI Data'!L12 | N27: ='Raw OI Data'!L13 | O27: ='Raw OI Data'!L14 | Q27: ='Raw OI Data'!L15 | R27: ='Raw OI Data'!L16 | S27: ='Raw OI Data'!L17 | T27: ='Raw OI Data'!L18 | V27: ='Raw OI Data'!L19 | W27: ='Raw OI Data'!L20 | X27: ='Raw OI Data'!L21 | Y27: ='Raw OI Data'!L22
A28: Put Short OI | B28: ='Raw OI Data'!N3 | C28: ='Raw OI Data'!N4 | D28: ='Raw OI Data'!N5 | E28: ='Raw OI Data'!N6 | G28: ='Raw OI Data'!N7 | H28: ='Raw OI Data'!N8 | I28: ='Raw OI Data'!N9 | J28: ='Raw OI Data'!N10 | L28: ='Raw OI Data'!N11 | M28: ='Raw OI Data'!N12 | N28: ='Raw OI Data'!N13 | O28: ='Raw OI Data'!N14 | Q28: ='Raw OI Data'!N15 | R28: ='Raw OI Data'!N16 | S28: ='Raw OI Data'!N17 | T28: ='Raw OI Data'!N18 | V28: ='Raw OI Data'!N19 | W28: ='Raw OI Data'!N20 | X28: ='Raw OI Data'!N21 | Y28: ='Raw OI Data'!N22
A29: Net Put OI | B29: ='Raw OI Data'!L3-'Raw OI Data'!N3 | C29: ='Raw OI Data'!L4-'Raw OI Data'!N4 | D29: ='Raw OI Data'!L5-'Raw OI Data'!N5 | E29: ='Raw OI Data'!L6-'Raw OI Data'!N6 | G29: ='Raw OI Data'!L7-'Raw OI Data'!N7 | H29: ='Raw OI Data'!L8-'Raw OI Data'!N8 | I29: ='Raw OI Data'!L9-'Raw OI Data'!N9 | J29: ='Raw OI Data'!L10-'Raw OI Data'!N10 | L29: ='Raw OI Data'!L11-'Raw OI Data'!N11 | M29: ='Raw OI Data'!L12-'Raw OI Data'!N12 | N29: ='Raw OI Data'!L13-'Raw OI Data'!N13 | O29: ='Raw OI Data'!L14-'Raw OI Data'!N14 | Q29: ='Raw OI Data'!L15-'Raw OI Data'!N15 | R29: ='Raw OI Data'!L16-'Raw OI Data'!N16 | S29: ='Raw OI Data'!L17-'Raw OI Data'!N17 | T29: ='Raw OI Data'!L18-'Raw OI Data'!N18 | V29: ='Raw OI Data'!L19-'Raw OI Data'!N19 | W29: ='Raw OI Data'!L20-'Raw OI Data'!N20 | X29: ='Raw OI Data'!L21-'Raw OI Data'!N21 | Y29: ='Raw OI Data'!L22-'Raw OI Data'!N22
A30: TOTAL POSITION
A31: Total Long | B31: ='Raw OI Data'!O3 | C31: ='Raw OI Data'!O4 | D31: ='Raw OI Data'!O5 | E31: ='Raw OI Data'!O6 | G31: ='Raw OI Data'!O7 | H31: ='Raw OI Data'!O8 | I31: ='Raw OI Data'!O9 | J31: ='Raw OI Data'!O10 | L31: ='Raw OI Data'!O11 | M31: ='Raw OI Data'!O12 | N31: ='Raw OI Data'!O13 | O31: ='Raw OI Data'!O14 | Q31: ='Raw OI Data'!O15 | R31: ='Raw OI Data'!O16 | S31: ='Raw OI Data'!O17 | T31: ='Raw OI Data'!O18 | V31: ='Raw OI Data'!O19 | W31: ='Raw OI Data'!O20 | X31: ='Raw OI Data'!O21 | Y31: ='Raw OI Data'!O22
A32: Total Short | B32: ='Raw OI Data'!P3 | C32: ='Raw OI Data'!P4 | D32: ='Raw OI Data'!P5 | E32: ='Raw OI Data'!P6 | G32: ='Raw OI Data'!P7 | H32: ='Raw OI Data'!P8 | I32: ='Raw OI Data'!P9 | J32: ='Raw OI Data'!P10 | L32: ='Raw OI Data'!P11 | M32: ='Raw OI Data'!P12 | N32: ='Raw OI Data'!P13 | O32: ='Raw OI Data'!P14 | Q32: ='Raw OI Data'!P15 | R32: ='Raw OI Data'!P16 | S32: ='Raw OI Data'!P17 | T32: ='Raw OI Data'!P18 | V32: ='Raw OI Data'!P19 | W32: ='Raw OI Data'!P20 | X32: ='Raw OI Data'!P21 | Y32: ='Raw OI Data'!P22
A33: Net Total OI | B33: ='Raw OI Data'!O3-'Raw OI Data'!P3 | C33: ='Raw OI Data'!O4-'Raw OI Data'!P4 | D33: ='Raw OI Data'!O5-'Raw OI Data'!P5 | E33: ='Raw OI Data'!O6-'Raw OI Data'!P6 | G33: ='Raw OI Data'!O7-'Raw OI Data'!P7 | H33: ='Raw OI Data'!O8-'Raw OI Data'!P8 | I33: ='Raw OI Data'!O9-'Raw OI Data'!P9 | J33: ='Raw OI Data'!O10-'Raw OI Data'!P10 | L33: ='Raw OI Data'!O11-'Raw OI Data'!P11 | M33: ='Raw OI Data'!O12-'Raw OI Data'!P12 | N33: ='Raw OI Data'!O13-'Raw OI Data'!P13 | O33: ='Raw OI Data'!O14-'Raw OI Data'!P14 | Q33: ='Raw OI Data'!O15-'Raw OI Data'!P15 | R33: ='Raw OI Data'!O16-'Raw OI Data'!P16 | S33: ='Raw OI Data'!O17-'Raw OI Data'!P17 | T33: ='Raw OI Data'!O18-'Raw OI Data'!P18 | V33: ='Raw OI Data'!O19-'Raw OI Data'!P19 | W33: ='Raw OI Data'!O20-'Raw OI Data'!P20 | X33: ='Raw OI Data'!O21-'Raw OI Data'!P21 | Y33: ='Raw OI Data'!O22-'Raw OI Data'!P22
A34: L/S Ratio | B34: =IFERROR('Raw OI Data'!O3/'Raw OI Data'!P3,0) | C34: =IFERROR('Raw OI Data'!O4/'Raw OI Data'!P4,0) | D34: =IFERROR('Raw OI Data'!O5/'Raw OI Data'!P5,0) | E34: =IFERROR('Raw OI Data'!O6/'Raw OI Data'!P6,0) | G34: =IFERROR('Raw OI Data'!O7/'Raw OI Data'!P7,0) | H34: =IFERROR('Raw OI Data'!O8/'Raw OI Data'!P8,0) | I34: =IFERROR('Raw OI Data'!O9/'Raw OI Data'!P9,0) | J34: =IFERROR('Raw OI Data'!O10/'Raw OI Data'!P10,0) | L34: =IFERROR('Raw OI Data'!O11/'Raw OI Data'!P11,0) | M34: =IFERROR('Raw OI Data'!O12/'Raw OI Data'!P12,0) | N34: =IFERROR('Raw OI Data'!O13/'Raw OI Data'!P13,0) | O34: =IFERROR('Raw OI Data'!O14/'Raw OI Data'!P14,0) | Q34: =IFERROR('Raw OI Data'!O15/'Raw OI Data'!P15,0) | R34: =IFERROR('Raw OI Data'!O16/'Raw OI Data'!P16,0) | S34: =IFERROR('Raw OI Data'!O17/'Raw OI Data'!P17,0) | T34: =IFERROR('Raw OI Data'!O18/'Raw OI Data'!P18,0) | V34: =IFERROR('Raw OI Data'!O19/'Raw OI Data'!P19,0) | W34: =IFERROR('Raw OI Data'!O20/'Raw OI Data'!P20,0) | X34: =IFERROR('Raw OI Data'!O21/'Raw OI Data'!P21,0) | Y34: =IFERROR('Raw OI Data'!O22/'Raw OI Data'!P22,0)
A35: % of Mkt Long | B35: =IFERROR('Raw OI Data'!O3/SUM('Raw OI Data'!O3,'Raw OI Data'!O4,'Raw OI Data'!O5,'Raw OI Data'!O6),0) | C35: =IFERROR('Raw OI Data'!O4/SUM('Raw OI Data'!O3,'Raw OI Data'!O4,'Raw OI Data'!O5,'Raw OI Data'!O6),0) | D35: =IFERROR('Raw OI Data'!O5/SUM('Raw OI Data'!O3,'Raw OI Data'!O4,'Raw OI Data'!O5,'Raw OI Data'!O6),0) | E35: =IFERROR('Raw OI Data'!O6/SUM('Raw OI Data'!O3,'Raw OI Data'!O4,'Raw OI Data'!O5,'Raw OI Data'!O6),0) | G35: =IFERROR('Raw OI Data'!O7/SUM('Raw OI Data'!O7,'Raw OI Data'!O8,'Raw OI Data'!O9,'Raw OI Data'!O10),0) | H35: =IFERROR('Raw OI Data'!O8/SUM('Raw OI Data'!O7,'Raw OI Data'!O8,'Raw OI Data'!O9,'Raw OI Data'!O10),0) | I35: =IFERROR('Raw OI Data'!O9/SUM('Raw OI Data'!O7,'Raw OI Data'!O8,'Raw OI Data'!O9,'Raw OI Data'!O10),0) | J35: =IFERROR('Raw OI Data'!O10/SUM('Raw OI Data'!O7,'Raw OI Data'!O8,'Raw OI Data'!O9,'Raw OI Data'!O10),0) | L35: =IFERROR('Raw OI Data'!O11/SUM('Raw OI Data'!O11,'Raw OI Data'!O12,'Raw OI Data'!O13,'Raw OI Data'!O14),0) | M35: =IFERROR('Raw OI Data'!O12/SUM('Raw OI Data'!O11,'Raw OI Data'!O12,'Raw OI Data'!O13,'Raw OI Data'!O14),0) | N35: =IFERROR('Raw OI Data'!O13/SUM('Raw OI Data'!O11,'Raw OI Data'!O12,'Raw OI Data'!O13,'Raw OI Data'!O14),0) | O35: =IFERROR('Raw OI Data'!O14/SUM('Raw OI Data'!O11,'Raw OI Data'!O12,'Raw OI Data'!O13,'Raw OI Data'!O14),0) | Q35: =IFERROR('Raw OI Data'!O15/SUM('Raw OI Data'!O15,'Raw OI Data'!O16,'Raw OI Data'!O17,'Raw OI Data'!O18),0) | R35: =IFERROR('Raw OI Data'!O16/SUM('Raw OI Data'!O15,'Raw OI Data'!O16,'Raw OI Data'!O17,'Raw OI Data'!O18),0) | S35: =IFERROR('Raw OI Data'!O17/SUM('Raw OI Data'!O15,'Raw OI Data'!O16,'Raw OI Data'!O17,'Raw OI Data'!O18),0) | T35: =IFERROR('Raw OI Data'!O18/SUM('Raw OI Data'!O15,'Raw OI Data'!O16,'Raw OI Data'!O17,'Raw OI Data'!O18),0) | V35: =IFERROR('Raw OI Data'!O19/SUM('Raw OI Data'!O19,'Raw OI Data'!O20,'Raw OI Data'!O21,'Raw OI Data'!O22),0) | W35: =IFERROR('Raw OI Data'!O20/SUM('Raw OI Data'!O19,'Raw OI Data'!O20,'Raw OI Data'!O21,'Raw OI Data'!O22),0) | X35: =IFERROR('Raw OI Data'!O21/SUM('Raw OI Data'!O19,'Raw OI Data'!O20,'Raw OI Data'!O21,'Raw OI Data'!O22),0) | Y35: =IFERROR('Raw OI Data'!O22/SUM('Raw OI Data'!O19,'Raw OI Data'!O20,'Raw OI Data'!O21,'Raw OI Data'!O22),0)
A36: % of Mkt Short | B36: =IFERROR('Raw OI Data'!P3/SUM('Raw OI Data'!P3,'Raw OI Data'!P4,'Raw OI Data'!P5,'Raw OI Data'!P6),0) | C36: =IFERROR('Raw OI Data'!P4/SUM('Raw OI Data'!P3,'Raw OI Data'!P4,'Raw OI Data'!P5,'Raw OI Data'!P6),0) | D36: =IFERROR('Raw OI Data'!P5/SUM('Raw OI Data'!P3,'Raw OI Data'!P4,'Raw OI Data'!P5,'Raw OI Data'!P6),0) | E36: =IFERROR('Raw OI Data'!P6/SUM('Raw OI Data'!P3,'Raw OI Data'!P4,'Raw OI Data'!P5,'Raw OI Data'!P6),0) | G36: =IFERROR('Raw OI Data'!P7/SUM('Raw OI Data'!P7,'Raw OI Data'!P8,'Raw OI Data'!P9,'Raw OI Data'!P10),0) | H36: =IFERROR('Raw OI Data'!P8/SUM('Raw OI Data'!P7,'Raw OI Data'!P8,'Raw OI Data'!P9,'Raw OI Data'!P10),0) | I36: =IFERROR('Raw OI Data'!P9/SUM('Raw OI Data'!P7,'Raw OI Data'!P8,'Raw OI Data'!P9,'Raw OI Data'!P10),0) | J36: =IFERROR('Raw OI Data'!P10/SUM('Raw OI Data'!P7,'Raw OI Data'!P8,'Raw OI Data'!P9,'Raw OI Data'!P10),0) | L36: =IFERROR('Raw OI Data'!P11/SUM('Raw OI Data'!P11,'Raw OI Data'!P12,'Raw OI Data'!P13,'Raw OI Data'!P14),0) | M36: =IFERROR('Raw OI Data'!P12/SUM('Raw OI Data'!P11,'Raw OI Data'!P12,'Raw OI Data'!P13,'Raw OI Data'!P14),0) | N36: =IFERROR('Raw OI Data'!P13/SUM('Raw OI Data'!P11,'Raw OI Data'!P12,'Raw OI Data'!P13,'Raw OI Data'!P14),0) | O36: =IFERROR('Raw OI Data'!P14/SUM('Raw OI Data'!P11,'Raw OI Data'!P12,'Raw OI Data'!P13,'Raw OI Data'!P14),0) | Q36: =IFERROR('Raw OI Data'!P15/SUM('Raw OI Data'!P15,'Raw OI Data'!P16,'Raw OI Data'!P17,'Raw OI Data'!P18),0) | R36: =IFERROR('Raw OI Data'!P16/SUM('Raw OI Data'!P15,'Raw OI Data'!P16,'Raw OI Data'!P17,'Raw OI Data'!P18),0) | S36: =IFERROR('Raw OI Data'!P17/SUM('Raw OI Data'!P15,'Raw OI Data'!P16,'Raw OI Data'!P17,'Raw OI Data'!P18),0) | T36: =IFERROR('Raw OI Data'!P18/SUM('Raw OI Data'!P15,'Raw OI Data'!P16,'Raw OI Data'!P17,'Raw OI Data'!P18),0) | V36: =IFERROR('Raw OI Data'!P19/SUM('Raw OI Data'!P19,'Raw OI Data'!P20,'Raw OI Data'!P21,'Raw OI Data'!P22),0) | W36: =IFERROR('Raw OI Data'!P20/SUM('Raw OI Data'!P19,'Raw OI Data'!P20,'Raw OI Data'!P21,'Raw OI Data'!P22),0) | X36: =IFERROR('Raw OI Data'!P21/SUM('Raw OI Data'!P19,'Raw OI Data'!P20,'Raw OI Data'!P21,'Raw OI Data'!P22),0) | Y36: =IFERROR('Raw OI Data'!P22/SUM('Raw OI Data'!P19,'Raw OI Data'!P20,'Raw OI Data'!P21,'Raw OI Data'!P22),0)

Sheet TV Dashboard
A1: NSE FAO — TV Dashboard
A2: Metric | B2: Jul 06 2026 | G2: Jul 07 2026 | L2: Jul 08 2026 | Q2: Jul 09 2026 | V2: Jul 10 2026
B3: Client | C3: DII | D3: FII | E3: Pro | G3: Client | H3: DII | I3: FII | J3: Pro | L3: Client | M3: DII | N3: FII | O3: Pro | Q3: Client | R3: DII | S3: FII | T3: Pro | V3: Client | W3: DII | X3: FII | Y3: Pro
A4: FUTURES — INDEX
A5: Buy Volume | B5: ='Raw TV Data'!C3 | C5: ='Raw TV Data'!C4 | D5: ='Raw TV Data'!C5 | E5: ='Raw TV Data'!C6 | G5: ='Raw TV Data'!C7 | H5: ='Raw TV Data'!C8 | I5: ='Raw TV Data'!C9 | J5: ='Raw TV Data'!C10 | L5: ='Raw TV Data'!C11 | M5: ='Raw TV Data'!C12 | N5: ='Raw TV Data'!C13 | O5: ='Raw TV Data'!C14 | Q5: ='Raw TV Data'!C15 | R5: ='Raw TV Data'!C16 | S5: ='Raw TV Data'!C17 | T5: ='Raw TV Data'!C18 | V5: ='Raw TV Data'!C19 | W5: ='Raw TV Data'!C20 | X5: ='Raw TV Data'!C21 | Y5: ='Raw TV Data'!C22
A6: Sell Volume | B6: ='Raw TV Data'!D3 | C6: ='Raw TV Data'!D4 | D6: ='Raw TV Data'!D5 | E6: ='Raw TV Data'!D6 | G6: ='Raw TV Data'!D7 | H6: ='Raw TV Data'!D8 | I6: ='Raw TV Data'!D9 | J6: ='Raw TV Data'!D10 | L6: ='Raw TV Data'!D11 | M6: ='Raw TV Data'!D12 | N6: ='Raw TV Data'!D13 | O6: ='Raw TV Data'!D14 | Q6: ='Raw TV Data'!D15 | R6: ='Raw TV Data'!D16 | S6: ='Raw TV Data'!D17 | T6: ='Raw TV Data'!D18 | V6: ='Raw TV Data'!D19 | W6: ='Raw TV Data'!D20 | X6: ='Raw TV Data'!D21 | Y6: ='Raw TV Data'!D22
A7: Net Volume (B−S) | B7: ='Raw TV Data'!C3-'Raw TV Data'!D3 | C7: ='Raw TV Data'!C4-'Raw TV Data'!D4 | D7: ='Raw TV Data'!C5-'Raw TV Data'!D5 | E7: ='Raw TV Data'!C6-'Raw TV Data'!D6 | G7: ='Raw TV Data'!C7-'Raw TV Data'!D7 | H7: ='Raw TV Data'!C8-'Raw TV Data'!D8 | I7: ='Raw TV Data'!C9-'Raw TV Data'!D9 | J7: ='Raw TV Data'!C10-'Raw TV Data'!D10 | L7: ='Raw TV Data'!C11-'Raw TV Data'!D11 | M7: ='Raw TV Data'!C12-'Raw TV Data'!D12 | N7: ='Raw TV Data'!C13-'Raw TV Data'!D13 | O7: ='Raw TV Data'!C14-'Raw TV Data'!D14 | Q7: ='Raw TV Data'!C15-'Raw TV Data'!D15 | R7: ='Raw TV Data'!C16-'Raw TV Data'!D16 | S7: ='Raw TV Data'!C17-'Raw TV Data'!D17 | T7: ='Raw TV Data'!C18-'Raw TV Data'!D18 | V7: ='Raw TV Data'!C19-'Raw TV Data'!D19 | W7: ='Raw TV Data'!C20-'Raw TV Data'!D20 | X7: ='Raw TV Data'!C21-'Raw TV Data'!D21 | Y7: ='Raw TV Data'!C22-'Raw TV Data'!D22
A8: FUTURES — STOCK
A9: Buy Volume | B9: ='Raw TV Data'!E3 | C9: ='Raw TV Data'!E4 | D9: ='Raw TV Data'!E5 | E9: ='Raw TV Data'!E6 | G9: ='Raw TV Data'!E7 | H9: ='Raw TV Data'!E8 | I9: ='Raw TV Data'!E9 | J9: ='Raw TV Data'!E10 | L9: ='Raw TV Data'!E11 | M9: ='Raw TV Data'!E12 | N9: ='Raw TV Data'!E13 | O9: ='Raw TV Data'!E14 | Q9: ='Raw TV Data'!E15 | R9: ='Raw TV Data'!E16 | S9: ='Raw TV Data'!E17 | T9: ='Raw TV Data'!E18 | V9: ='Raw TV Data'!E19 | W9: ='Raw TV Data'!E20 | X9: ='Raw TV Data'!E21 | Y9: ='Raw TV Data'!E22
A10: Sell Volume | B10: ='Raw TV Data'!F3 | C10: ='Raw TV Data'!F4 | D10: ='Raw TV Data'!F5 | E10: ='Raw TV Data'!F6 | G10: ='Raw TV Data'!F7 | H10: ='Raw TV Data'!F8 | I10: ='Raw TV Data'!F9 | J10: ='Raw TV Data'!F10 | L10: ='Raw TV Data'!F11 | M10: ='Raw TV Data'!F12 | N10: ='Raw TV Data'!F13 | O10: ='Raw TV Data'!F14 | Q10: ='Raw TV Data'!F15 | R10: ='Raw TV Data'!F16 | S10: ='Raw TV Data'!F17 | T10: ='Raw TV Data'!F18 | V10: ='Raw TV Data'!F19 | W10: ='Raw TV Data'!F20 | X10: ='Raw TV Data'!F21 | Y10: ='Raw TV Data'!F22
A11: Net Volume (B−S) | B11: ='Raw TV Data'!E3-'Raw TV Data'!F3 | C11: ='Raw TV Data'!E4-'Raw TV Data'!F4 | D11: ='Raw TV Data'!E5-'Raw TV Data'!F5 | E11: ='Raw TV Data'!E6-'Raw TV Data'!F6 | G11: ='Raw TV Data'!E7-'Raw TV Data'!F7 | H11: ='Raw TV Data'!E8-'Raw TV Data'!F8 | I11: ='Raw TV Data'!E9-'Raw TV Data'!F9 | J11: ='Raw TV Data'!E10-'Raw TV Data'!F10 | L11: ='Raw TV Data'!E11-'Raw TV Data'!F11 | M11: ='Raw TV Data'!E12-'Raw TV Data'!F12 | N11: ='Raw TV Data'!E13-'Raw TV Data'!F13 | O11: ='Raw TV Data'!E14-'Raw TV Data'!F14 | Q11: ='Raw TV Data'!E15-'Raw TV Data'!F15 | R11: ='Raw TV Data'!E16-'Raw TV Data'!F16 | S11: ='Raw TV Data'!E17-'Raw TV Data'!F17 | T11: ='Raw TV Data'!E18-'Raw TV Data'!F18 | V11: ='Raw TV Data'!E19-'Raw TV Data'!F19 | W11: ='Raw TV Data'!E20-'Raw TV Data'!F20 | X11: ='Raw TV Data'!E21-'Raw TV Data'!F21 | Y11: ='Raw TV Data'!E22-'Raw TV Data'!F22
A12: OPTIONS — INDEX
A13: Call Buy Volume | B13: ='Raw TV Data'!G3 | C13: ='Raw TV Data'!G4 | D13: ='Raw TV Data'!G5 | E13: ='Raw TV Data'!G6 | G13: ='Raw TV Data'!G7 | H13: ='Raw TV Data'!G8 | I13: ='Raw TV Data'!G9 | J13: ='Raw TV Data'!G10 | L13: ='Raw TV Data'!G11 | M13: ='Raw TV Data'!G12 | N13: ='Raw TV Data'!G13 | O13: ='Raw TV Data'!G14 | Q13: ='Raw TV Data'!G15 | R13: ='Raw TV Data'!G16 | S13: ='Raw TV Data'!G17 | T13: ='Raw TV Data'!G18 | V13: ='Raw TV Data'!G19 | W13: ='Raw TV Data'!G20 | X13: ='Raw TV Data'!G21 | Y13: ='Raw TV Data'!G22
A14: Put Buy Volume | B14: ='Raw TV Data'!H3 | C14: ='Raw TV Data'!H4 | D14: ='Raw TV Data'!H5 | E14: ='Raw TV Data'!H6 | G14: ='Raw TV Data'!H7 | H14: ='Raw TV Data'!H8 | I14: ='Raw TV Data'!H9 | J14: ='Raw TV Data'!H10 | L14: ='Raw TV Data'!H11 | M14: ='Raw TV Data'!H12 | N14: ='Raw TV Data'!H13 | O14: ='Raw TV Data'!H14 | Q14: ='Raw TV Data'!H15 | R14: ='Raw TV Data'!H16 | S14: ='Raw TV Data'!H17 | T14: ='Raw TV Data'!H18 | V14: ='Raw TV Data'!H19 | W14: ='Raw TV Data'!H20 | X14: ='Raw TV Data'!H21 | Y14: ='Raw TV Data'!H22
A15: Volume PCR | B15: =IFERROR('Raw TV Data'!H3/'Raw TV Data'!G3,0) | C15: =IFERROR('Raw TV Data'!H4/'Raw TV Data'!G4,0) | D15: =IFERROR('Raw TV Data'!H5/'Raw TV Data'!G5,0) | E15: =IFERROR('Raw TV Data'!H6/'Raw TV Data'!G6,0) | G15: =IFERROR('Raw TV Data'!H7/'Raw TV Data'!G7,0) | H15: =IFERROR('Raw TV Data'!H8/'Raw TV Data'!G8,0) | I15: =IFERROR('Raw TV Data'!H9/'Raw TV Data'!G9,0) | J15: =IFERROR('Raw TV Data'!H10/'Raw TV Data'!G10,0) | L15: =IFERROR('Raw TV Data'!H11/'Raw TV Data'!G11,0) | M15: =IFERROR('Raw TV Data'!H12/'Raw TV Data'!G12,0) | N15: =IFERROR('Raw TV Data'!H13/'Raw TV Data'!G13,0) | O15: =IFERROR('Raw TV Data'!H14/'Raw TV Data'!G14,0) | Q15: =IFERROR('Raw TV Data'!H15/'Raw TV Data'!G15,0) | R15: =IFERROR('Raw TV Data'!H16/'Raw TV Data'!G16,0) | S15: =IFERROR('Raw TV Data'!H17/'Raw TV Data'!G17,0) | T15: =IFERROR('Raw TV Data'!H18/'Raw TV Data'!G18,0) | V15: =IFERROR('Raw TV Data'!H19/'Raw TV Data'!G19,0) | W15: =IFERROR('Raw TV Data'!H20/'Raw TV Data'!G20,0) | X15: =IFERROR('Raw TV Data'!H21/'Raw TV Data'!G21,0) | Y15: =IFERROR('Raw TV Data'!H22/'Raw TV Data'!G22,0)
A16: Call Sell Volume | B16: ='Raw TV Data'!I3 | C16: ='Raw TV Data'!I4 | D16: ='Raw TV Data'!I5 | E16: ='Raw TV Data'!I6 | G16: ='Raw TV Data'!I7 | H16: ='Raw TV Data'!I8 | I16: ='Raw TV Data'!I9 | J16: ='Raw TV Data'!I10 | L16: ='Raw TV Data'!I11 | M16: ='Raw TV Data'!I12 | N16: ='Raw TV Data'!I13 | O16: ='Raw TV Data'!I14 | Q16: ='Raw TV Data'!I15 | R16: ='Raw TV Data'!I16 | S16: ='Raw TV Data'!I17 | T16: ='Raw TV Data'!I18 | V16: ='Raw TV Data'!I19 | W16: ='Raw TV Data'!I20 | X16: ='Raw TV Data'!I21 | Y16: ='Raw TV Data'!I22
A17: Put Sell Volume | B17: ='Raw TV Data'!J3 | C17: ='Raw TV Data'!J4 | D17: ='Raw TV Data'!J5 | E17: ='Raw TV Data'!J6 | G17: ='Raw TV Data'!J7 | H17: ='Raw TV Data'!J8 | I17: ='Raw TV Data'!J9 | J17: ='Raw TV Data'!J10 | L17: ='Raw TV Data'!J11 | M17: ='Raw TV Data'!J12 | N17: ='Raw TV Data'!J13 | O17: ='Raw TV Data'!J14 | Q17: ='Raw TV Data'!J15 | R17: ='Raw TV Data'!J16 | S17: ='Raw TV Data'!J17 | T17: ='Raw TV Data'!J18 | V17: ='Raw TV Data'!J19 | W17: ='Raw TV Data'!J20 | X17: ='Raw TV Data'!J21 | Y17: ='Raw TV Data'!J22
A18: OPTIONS — STOCK
A19: Call Buy Volume | B19: ='Raw TV Data'!K3 | C19: ='Raw TV Data'!K4 | D19: ='Raw TV Data'!K5 | E19: ='Raw TV Data'!K6 | G19: ='Raw TV Data'!K7 | H19: ='Raw TV Data'!K8 | I19: ='Raw TV Data'!K9 | J19: ='Raw TV Data'!K10 | L19: ='Raw TV Data'!K11 | M19: ='Raw TV Data'!K12 | N19: ='Raw TV Data'!K13 | O19: ='Raw TV Data'!K14 | Q19: ='Raw TV Data'!K15 | R19: ='Raw TV Data'!K16 | S19: ='Raw TV Data'!K17 | T19: ='Raw TV Data'!K18 | V19: ='Raw TV Data'!K19 | W19: ='Raw TV Data'!K20 | X19: ='Raw TV Data'!K21 | Y19: ='Raw TV Data'!K22
A20: Put Buy Volume | B20: ='Raw TV Data'!L3 | C20: ='Raw TV Data'!L4 | D20: ='Raw TV Data'!L5 | E20: ='Raw TV Data'!L6 | G20: ='Raw TV Data'!L7 | H20: ='Raw TV Data'!L8 | I20: ='Raw TV Data'!L9 | J20: ='Raw TV Data'!L10 | L20: ='Raw TV Data'!L11 | M20: ='Raw TV Data'!L12 | N20: ='Raw TV Data'!L13 | O20: ='Raw TV Data'!L14 | Q20: ='Raw TV Data'!L15 | R20: ='Raw TV Data'!L16 | S20: ='Raw TV Data'!L17 | T20: ='Raw TV Data'!L18 | V20: ='Raw TV Data'!L19 | W20: ='Raw TV Data'!L20 | X20: ='Raw TV Data'!L21 | Y20: ='Raw TV Data'!L22
A21: Volume PCR | B21: =IFERROR('Raw TV Data'!L3/'Raw TV Data'!K3,0) | C21: =IFERROR('Raw TV Data'!L4/'Raw TV Data'!K4,0) | D21: =IFERROR('Raw TV Data'!L5/'Raw TV Data'!K5,0) | E21: =IFERROR('Raw TV Data'!L6/'Raw TV Data'!K6,0) | G21: =IFERROR('Raw TV Data'!L7/'Raw TV Data'!K7,0) | H21: =IFERROR('Raw TV Data'!L8/'Raw TV Data'!K8,0) | I21: =IFERROR('Raw TV Data'!L9/'Raw TV Data'!K9,0) | J21: =IFERROR('Raw TV Data'!L10/'Raw TV Data'!K10,0) | L21: =IFERROR('Raw TV Data'!L11/'Raw TV Data'!K11,0) | M21: =IFERROR('Raw TV Data'!L12/'Raw TV Data'!K12,0) | N21: =IFERROR('Raw TV Data'!L13/'Raw TV Data'!K13,0) | O21: =IFERROR('Raw TV Data'!L14/'Raw TV Data'!K14,0) | Q21: =IFERROR('Raw TV Data'!L15/'Raw TV Data'!K15,0) | R21: =IFERROR('Raw TV Data'!L16/'Raw TV Data'!K16,0) | S21: =IFERROR('Raw TV Data'!L17/'Raw TV Data'!K17,0) | T21: =IFERROR('Raw TV Data'!L18/'Raw TV Data'!K18,0) | V21: =IFERROR('Raw TV Data'!L19/'Raw TV Data'!K19,0) | W21: =IFERROR('Raw TV Data'!L20/'Raw TV Data'!K20,0) | X21: =IFERROR('Raw TV Data'!L21/'Raw TV Data'!K21,0) | Y21: =IFERROR('Raw TV Data'!L22/'Raw TV Data'!K22,0)
A22: Call Sell Volume | B22: ='Raw TV Data'!M3 | C22: ='Raw TV Data'!M4 | D22: ='Raw TV Data'!M5 | E22: ='Raw TV Data'!M6 | G22: ='Raw TV Data'!M7 | H22: ='Raw TV Data'!M8 | I22: ='Raw TV Data'!M9 | J22: ='Raw TV Data'!M10 | L22: ='Raw TV Data'!M11 | M22: ='Raw TV Data'!M12 | N22: ='Raw TV Data'!M13 | O22: ='Raw TV Data'!M14 | Q22: ='Raw TV Data'!M15 | R22: ='Raw TV Data'!M16 | S22: ='Raw TV Data'!M17 | T22: ='Raw TV Data'!M18 | V22: ='Raw TV Data'!M19 | W22: ='Raw TV Data'!M20 | X22: ='Raw TV Data'!M21 | Y22: ='Raw TV Data'!M22
A23: Put Sell Volume | B23: ='Raw TV Data'!N3 | C23: ='Raw TV Data'!N4 | D23: ='Raw TV Data'!N5 | E23: ='Raw TV Data'!N6 | G23: ='Raw TV Data'!N7 | H23: ='Raw TV Data'!N8 | I23: ='Raw TV Data'!N9 | J23: ='Raw TV Data'!N10 | L23: ='Raw TV Data'!N11 | M23: ='Raw TV Data'!N12 | N23: ='Raw TV Data'!N13 | O23: ='Raw TV Data'!N14 | Q23: ='Raw TV Data'!N15 | R23: ='Raw TV Data'!N16 | S23: ='Raw TV Data'!N17 | T23: ='Raw TV Data'!N18 | V23: ='Raw TV Data'!N19 | W23: ='Raw TV Data'!N20 | X23: ='Raw TV Data'!N21 | Y23: ='Raw TV Data'!N22
A24: TOTAL VOLUME
A25: Total Buy | B25: ='Raw TV Data'!O3 | C25: ='Raw TV Data'!O4 | D25: ='Raw TV Data'!O5 | E25: ='Raw TV Data'!O6 | G25: ='Raw TV Data'!O7 | H25: ='Raw TV Data'!O8 | I25: ='Raw TV Data'!O9 | J25: ='Raw TV Data'!O10 | L25: ='Raw TV Data'!O11 | M25: ='Raw TV Data'!O12 | N25: ='Raw TV Data'!O13 | O25: ='Raw TV Data'!O14 | Q25: ='Raw TV Data'!O15 | R25: ='Raw TV Data'!O16 | S25: ='Raw TV Data'!O17 | T25: ='Raw TV Data'!O18 | V25: ='Raw TV Data'!O19 | W25: ='Raw TV Data'!O20 | X25: ='Raw TV Data'!O21 | Y25: ='Raw TV Data'!O22
A26: Total Sell | B26: ='Raw TV Data'!P3 | C26: ='Raw TV Data'!P4 | D26: ='Raw TV Data'!P5 | E26: ='Raw TV Data'!P6 | G26: ='Raw TV Data'!P7 | H26: ='Raw TV Data'!P8 | I26: ='Raw TV Data'!P9 | J26: ='Raw TV Data'!P10 | L26: ='Raw TV Data'!P11 | M26: ='Raw TV Data'!P12 | N26: ='Raw TV Data'!P13 | O26: ='Raw TV Data'!P14 | Q26: ='Raw TV Data'!P15 | R26: ='Raw TV Data'!P16 | S26: ='Raw TV Data'!P17 | T26: ='Raw TV Data'!P18 | V26: ='Raw TV Data'!P19 | W26: ='Raw TV Data'!P20 | X26: ='Raw TV Data'!P21 | Y26: ='Raw TV Data'!P22
A27: Net Volume | B27: ='Raw TV Data'!O3-'Raw TV Data'!P3 | C27: ='Raw TV Data'!O4-'Raw TV Data'!P4 | D27: ='Raw TV Data'!O5-'Raw TV Data'!P5 | E27: ='Raw TV Data'!O6-'Raw TV Data'!P6 | G27: ='Raw TV Data'!O7-'Raw TV Data'!P7 | H27: ='Raw TV Data'!O8-'Raw TV Data'!P8 | I27: ='Raw TV Data'!O9-'Raw TV Data'!P9 | J27: ='Raw TV Data'!O10-'Raw TV Data'!P10 | L27: ='Raw TV Data'!O11-'Raw TV Data'!P11 | M27: ='Raw TV Data'!O12-'Raw TV Data'!P12 | N27: ='Raw TV Data'!O13-'Raw TV Data'!P13 | O27: ='Raw TV Data'!O14-'Raw TV Data'!P14 | Q27: ='Raw TV Data'!O15-'Raw TV Data'!P15 | R27: ='Raw TV Data'!O16-'Raw TV Data'!P16 | S27: ='Raw TV Data'!O17-'Raw TV Data'!P17 | T27: ='Raw TV Data'!O18-'Raw TV Data'!P18 | V27: ='Raw TV Data'!O19-'Raw TV Data'!P19 | W27: ='Raw TV Data'!O20-'Raw TV Data'!P20 | X27: ='Raw TV Data'!O21-'Raw TV Data'!P21 | Y27: ='Raw TV Data'!O22-'Raw TV Data'!P22
A28: % of Market Buy | B28: =IFERROR('Raw TV Data'!O3/SUM('Raw TV Data'!O3,'Raw TV Data'!O4,'Raw TV Data'!O5,'Raw TV Data'!O6),0) | C28: =IFERROR('Raw TV Data'!O4/SUM('Raw TV Data'!O3,'Raw TV Data'!O4,'Raw TV Data'!O5,'Raw TV Data'!O6),0) | D28: =IFERROR('Raw TV Data'!O5/SUM('Raw TV Data'!O3,'Raw TV Data'!O4,'Raw TV Data'!O5,'Raw TV Data'!O6),0) | E28: =IFERROR('Raw TV Data'!O6/SUM('Raw TV Data'!O3,'Raw TV Data'!O4,'Raw TV Data'!O5,'Raw TV Data'!O6),0) | G28: =IFERROR('Raw TV Data'!O7/SUM('Raw TV Data'!O7,'Raw TV Data'!O8,'Raw TV Data'!O9,'Raw TV Data'!O10),0) | H28: =IFERROR('Raw TV Data'!O8/SUM('Raw TV Data'!O7,'Raw TV Data'!O8,'Raw TV Data'!O9,'Raw TV Data'!O10),0) | I28: =IFERROR('Raw TV Data'!O9/SUM('Raw TV Data'!O7,'Raw TV Data'!O8,'Raw TV Data'!O9,'Raw TV Data'!O10),0) | J28: =IFERROR('Raw TV Data'!O10/SUM('Raw TV Data'!O7,'Raw TV Data'!O8,'Raw TV Data'!O9,'Raw TV Data'!O10),0) | L28: =IFERROR('Raw TV Data'!O11/SUM('Raw TV Data'!O11,'Raw TV Data'!O12,'Raw TV Data'!O13,'Raw TV Data'!O14),0) | M28: =IFERROR('Raw TV Data'!O12/SUM('Raw TV Data'!O11,'Raw TV Data'!O12,'Raw TV Data'!O13,'Raw TV Data'!O14),0) | N28: =IFERROR('Raw TV Data'!O13/SUM('Raw TV Data'!O11,'Raw TV Data'!O12,'Raw TV Data'!O13,'Raw TV Data'!O14),0) | O28: =IFERROR('Raw TV Data'!O14/SUM('Raw TV Data'!O11,'Raw TV Data'!O12,'Raw TV Data'!O13,'Raw TV Data'!O14),0) | Q28: =IFERROR('Raw TV Data'!O15/SUM('Raw TV Data'!O15,'Raw TV Data'!O16,'Raw TV Data'!O17,'Raw TV Data'!O18),0) | R28: =IFERROR('Raw TV Data'!O16/SUM('Raw TV Data'!O15,'Raw TV Data'!O16,'Raw TV Data'!O17,'Raw TV Data'!O18),0) | S28: =IFERROR('Raw TV Data'!O17/SUM('Raw TV Data'!O15,'Raw TV Data'!O16,'Raw TV Data'!O17,'Raw TV Data'!O18),0) | T28: =IFERROR('Raw TV Data'!O18/SUM('Raw TV Data'!O15,'Raw TV Data'!O16,'Raw TV Data'!O17,'Raw TV Data'!O18),0) | V28: =IFERROR('Raw TV Data'!O19/SUM('Raw TV Data'!O19,'Raw TV Data'!O20,'Raw TV Data'!O21,'Raw TV Data'!O22),0) | W28: =IFERROR('Raw TV Data'!O20/SUM('Raw TV Data'!O19,'Raw TV Data'!O20,'Raw TV Data'!O21,'Raw TV Data'!O22),0) | X28: =IFERROR('Raw TV Data'!O21/SUM('Raw TV Data'!O19,'Raw TV Data'!O20,'Raw TV Data'!O21,'Raw TV Data'!O22),0) | Y28: =IFERROR('Raw TV Data'!O22/SUM('Raw TV Data'!O19,'Raw TV Data'!O20,'Raw TV Data'!O21,'Raw TV Data'!O22),0)

Sheet Net OI & Bias
A1: NSE FAO — Net OI & Market Bias by Participant
A2: Metric | B2: Jul 06 2026 | G2: Jul 07 2026 | L2: Jul 08 2026 | Q2: Jul 09 2026 | V2: Jul 10 2026
B3: Client | C3: DII | D3: FII | E3: Pro | G3: Client | H3: DII | I3: FII | J3: Pro | L3: Client | M3: DII | N3: FII | O3: Pro | Q3: Client | R3: DII | S3: FII | T3: Pro | V3: Client | W3: DII | X3: FII | Y3: Pro
A4: NET OPEN INTEREST (Long − Short)
A5: Net Fut Index OI | B5: ='Raw OI Data'!C3-'Raw OI Data'!D3 | C5: ='Raw OI Data'!C4-'Raw OI Data'!D4 | D5: ='Raw OI Data'!C5-'Raw OI Data'!D5 | E5: ='Raw OI Data'!C6-'Raw OI Data'!D6 | G5: ='Raw OI Data'!C7-'Raw OI Data'!D7 | H5: ='Raw OI Data'!C8-'Raw OI Data'!D8 | I5: ='Raw OI Data'!C9-'Raw OI Data'!D9 | J5: ='Raw OI Data'!C10-'Raw OI Data'!D10 | L5: ='Raw OI Data'!C11-'Raw OI Data'!D11 | M5: ='Raw OI Data'!C12-'Raw OI Data'!D12 | N5: ='Raw OI Data'!C13-'Raw OI Data'!D13 | O5: ='Raw OI Data'!C14-'Raw OI Data'!D14 | Q5: ='Raw OI Data'!C15-'Raw OI Data'!D15 | R5: ='Raw OI Data'!C16-'Raw OI Data'!D16 | S5: ='Raw OI Data'!C17-'Raw OI Data'!D17 | T5: ='Raw OI Data'!C18-'Raw OI Data'!D18 | V5: ='Raw OI Data'!C19-'Raw OI Data'!D19 | W5: ='Raw OI Data'!C20-'Raw OI Data'!D20 | X5: ='Raw OI Data'!C21-'Raw OI Data'!D21 | Y5: ='Raw OI Data'!C22-'Raw OI Data'!D22
A6: Net Fut Stock OI | B6: ='Raw OI Data'!E3-'Raw OI Data'!F3 | C6: ='Raw OI Data'!E4-'Raw OI Data'!F4 | D6: ='Raw OI Data'!E5-'Raw OI Data'!F5 | E6: ='Raw OI Data'!E6-'Raw OI Data'!F6 | G6: ='Raw OI Data'!E7-'Raw OI Data'!F7 | H6: ='Raw OI Data'!E8-'Raw OI Data'!F8 | I6: ='Raw OI Data'!E9-'Raw OI Data'!F9 | J6: ='Raw OI Data'!E10-'Raw OI Data'!F10 | L6: ='Raw OI Data'!E11-'Raw OI Data'!F11 | M6: ='Raw OI Data'!E12-'Raw OI Data'!F12 | N6: ='Raw OI Data'!E13-'Raw OI Data'!F13 | O6: ='Raw OI Data'!E14-'Raw OI Data'!F14 | Q6: ='Raw OI Data'!E15-'Raw OI Data'!F15 | R6: ='Raw OI Data'!E16-'Raw OI Data'!F16 | S6: ='Raw OI Data'!E17-'Raw OI Data'!F17 | T6: ='Raw OI Data'!E18-'Raw OI Data'!F18 | V6: ='Raw OI Data'!E19-'Raw OI Data'!F19 | W6: ='Raw OI Data'!E20-'Raw OI Data'!F20 | X6: ='Raw OI Data'!E21-'Raw OI Data'!F21 | Y6: ='Raw OI Data'!E22-'Raw OI Data'!F22
A7: Net Futures OI | B7: =('Raw OI Data'!C3+'Raw OI Data'!E3)-('Raw OI Data'!D3+'Raw OI Data'!F3) | C7: =('Raw OI Data'!C4+'Raw OI Data'!E4)-('Raw OI Data'!D4+'Raw OI Data'!F4) | D7: =('Raw OI Data'!C5+'Raw OI Data'!E5)-('Raw OI Data'!D5+'Raw OI Data'!F5) | E7: =('Raw OI Data'!C6+'Raw OI Data'!E6)-('Raw OI Data'!D6+'Raw OI Data'!F6) | G7: =('Raw OI Data'!C7+'Raw OI Data'!E7)-('Raw OI Data'!D7+'Raw OI Data'!F7) | H7: =('Raw OI Data'!C8+'Raw OI Data'!E8)-('Raw OI Data'!D8+'Raw OI Data'!F8) | I7: =('Raw OI Data'!C9+'Raw OI Data'!E9)-('Raw OI Data'!D9+'Raw OI Data'!F9) | J7: =('Raw OI Data'!C10+'Raw OI Data'!E10)-('Raw OI Data'!D10+'Raw OI Data'!F10) | L7: =('Raw OI Data'!C11+'Raw OI Data'!E11)-('Raw OI Data'!D11+'Raw OI Data'!F11) | M7: =('Raw OI Data'!C12+'Raw OI Data'!E12)-('Raw OI Data'!D12+'Raw OI Data'!F12) | N7: =('Raw OI Data'!C13+'Raw OI Data'!E13)-('Raw OI Data'!D13+'Raw OI Data'!F13) | O7: =('Raw OI Data'!C14+'Raw OI Data'!E14)-('Raw OI Data'!D14+'Raw OI Data'!F14) | Q7: =('Raw OI Data'!C15+'Raw OI Data'!E15)-('Raw OI Data'!D15+'Raw OI Data'!F15) | R7: =('Raw OI Data'!C16+'Raw OI Data'!E16)-('Raw OI Data'!D16+'Raw OI Data'!F16) | S7: =('Raw OI Data'!C17+'Raw OI Data'!E17)-('Raw OI Data'!D17+'Raw OI Data'!F17) | T7: =('Raw OI Data'!C18+'Raw OI Data'!E18)-('Raw OI Data'!D18+'Raw OI Data'!F18) | V7: =('Raw OI Data'!C19+'Raw OI Data'!E19)-('Raw OI Data'!D19+'Raw OI Data'!F19) | W7: =('Raw OI Data'!C20+'Raw OI Data'!E20)-('Raw OI Data'!D20+'Raw OI Data'!F20) | X7: =('Raw OI Data'!C21+'Raw OI Data'!E21)-('Raw OI Data'!D21+'Raw OI Data'!F21) | Y7: =('Raw OI Data'!C22+'Raw OI Data'!E22)-('Raw OI Data'!D22+'Raw OI Data'!F22)
A8: Net Idx Call OI | B8: ='Raw OI Data'!G3-'Raw OI Data'!I3 | C8: ='Raw OI Data'!G4-'Raw OI Data'!I4 | D8: ='Raw OI Data'!G5-'Raw OI Data'!I5 | E8: ='Raw OI Data'!G6-'Raw OI Data'!I6 | G8: ='Raw OI Data'!G7-'Raw OI Data'!I7 | H8: ='Raw OI Data'!G8-'Raw OI Data'!I8 | I8: ='Raw OI Data'!G9-'Raw OI Data'!I9 | J8: ='Raw OI Data'!G10-'Raw OI Data'!I10 | L8: ='Raw OI Data'!G11-'Raw OI Data'!I11 | M8: ='Raw OI Data'!G12-'Raw OI Data'!I12 | N8: ='Raw OI Data'!G13-'Raw OI Data'!I13 | O8: ='Raw OI Data'!G14-'Raw OI Data'!I14 | Q8: ='Raw OI Data'!G15-'Raw OI Data'!I15 | R8: ='Raw OI Data'!G16-'Raw OI Data'!I16 | S8: ='Raw OI Data'!G17-'Raw OI Data'!I17 | T8: ='Raw OI Data'!G18-'Raw OI Data'!I18 | V8: ='Raw OI Data'!G19-'Raw OI Data'!I19 | W8: ='Raw OI Data'!G20-'Raw OI Data'!I20 | X8: ='Raw OI Data'!G21-'Raw OI Data'!I21 | Y8: ='Raw OI Data'!G22-'Raw OI Data'!I22
A9: Net Idx Put OI | B9: ='Raw OI Data'!H3-'Raw OI Data'!J3 | C9: ='Raw OI Data'!H4-'Raw OI Data'!J4 | D9: ='Raw OI Data'!H5-'Raw OI Data'!J5 | E9: ='Raw OI Data'!H6-'Raw OI Data'!J6 | G9: ='Raw OI Data'!H7-'Raw OI Data'!J7 | H9: ='Raw OI Data'!H8-'Raw OI Data'!J8 | I9: ='Raw OI Data'!H9-'Raw OI Data'!J9 | J9: ='Raw OI Data'!H10-'Raw OI Data'!J10 | L9: ='Raw OI Data'!H11-'Raw OI Data'!J11 | M9: ='Raw OI Data'!H12-'Raw OI Data'!J12 | N9: ='Raw OI Data'!H13-'Raw OI Data'!J13 | O9: ='Raw OI Data'!H14-'Raw OI Data'!J14 | Q9: ='Raw OI Data'!H15-'Raw OI Data'!J15 | R9: ='Raw OI Data'!H16-'Raw OI Data'!J16 | S9: ='Raw OI Data'!H17-'Raw OI Data'!J17 | T9: ='Raw OI Data'!H18-'Raw OI Data'!J18 | V9: ='Raw OI Data'!H19-'Raw OI Data'!J19 | W9: ='Raw OI Data'!H20-'Raw OI Data'!J20 | X9: ='Raw OI Data'!H21-'Raw OI Data'!J21 | Y9: ='Raw OI Data'!H22-'Raw OI Data'!J22
A10: Net Stk Call OI | B10: ='Raw OI Data'!K3-'Raw OI Data'!M3 | C10: ='Raw OI Data'!K4-'Raw OI Data'!M4 | D10: ='Raw OI Data'!K5-'Raw OI Data'!M5 | E10: ='Raw OI Data'!K6-'Raw OI Data'!M6 | G10: ='Raw OI Data'!K7-'Raw OI Data'!M7 | H10: ='Raw OI Data'!K8-'Raw OI Data'!M8 | I10: ='Raw OI Data'!K9-'Raw OI Data'!M9 | J10: ='Raw OI Data'!K10-'Raw OI Data'!M10 | L10: ='Raw OI Data'!K11-'Raw OI Data'!M11 | M10: ='Raw OI Data'!K12-'Raw OI Data'!M12 | N10: ='Raw OI Data'!K13-'Raw OI Data'!M13 | O10: ='Raw OI Data'!K14-'Raw OI Data'!M14 | Q10: ='Raw OI Data'!K15-'Raw OI Data'!M15 | R10: ='Raw OI Data'!K16-'Raw OI Data'!M16 | S10: ='Raw OI Data'!K17-'Raw OI Data'!M17 | T10: ='Raw OI Data'!K18-'Raw OI Data'!M18 | V10: ='Raw OI Data'!K19-'Raw OI Data'!M19 | W10: ='Raw OI Data'!K20-'Raw OI Data'!M20 | X10: ='Raw OI Data'!K21-'Raw OI Data'!M21 | Y10: ='Raw OI Data'!K22-'Raw OI Data'!M22
A11: Net Stk Put OI | B11: ='Raw OI Data'!L3-'Raw OI Data'!N3 | C11: ='Raw OI Data'!L4-'Raw OI Data'!N4 | D11: ='Raw OI Data'!L5-'Raw OI Data'!N5 | E11: ='Raw OI Data'!L6-'Raw OI Data'!N6 | G11: ='Raw OI Data'!L7-'Raw OI Data'!N7 | H11: ='Raw OI Data'!L8-'Raw OI Data'!N8 | I11: ='Raw OI Data'!L9-'Raw OI Data'!N9 | J11: ='Raw OI Data'!L10-'Raw OI Data'!N10 | L11: ='Raw OI Data'!L11-'Raw OI Data'!N11 | M11: ='Raw OI Data'!L12-'Raw OI Data'!N12 | N11: ='Raw OI Data'!L13-'Raw OI Data'!N13 | O11: ='Raw OI Data'!L14-'Raw OI Data'!N14 | Q11: ='Raw OI Data'!L15-'Raw OI Data'!N15 | R11: ='Raw OI Data'!L16-'Raw OI Data'!N16 | S11: ='Raw OI Data'!L17-'Raw OI Data'!N17 | T11: ='Raw OI Data'!L18-'Raw OI Data'!N18 | V11: ='Raw OI Data'!L19-'Raw OI Data'!N19 | W11: ='Raw OI Data'!L20-'Raw OI Data'!N20 | X11: ='Raw OI Data'!L21-'Raw OI Data'!N21 | Y11: ='Raw OI Data'!L22-'Raw OI Data'!N22
A12: Net Total OI | B12: ='Raw OI Data'!O3-'Raw OI Data'!P3 | C12: ='Raw OI Data'!O4-'Raw OI Data'!P4 | D12: ='Raw OI Data'!O5-'Raw OI Data'!P5 | E12: ='Raw OI Data'!O6-'Raw OI Data'!P6 | G12: ='Raw OI Data'!O7-'Raw OI Data'!P7 | H12: ='Raw OI Data'!O8-'Raw OI Data'!P8 | I12: ='Raw OI Data'!O9-'Raw OI Data'!P9 | J12: ='Raw OI Data'!O10-'Raw OI Data'!P10 | L12: ='Raw OI Data'!O11-'Raw OI Data'!P11 | M12: ='Raw OI Data'!O12-'Raw OI Data'!P12 | N12: ='Raw OI Data'!O13-'Raw OI Data'!P13 | O12: ='Raw OI Data'!O14-'Raw OI Data'!P14 | Q12: ='Raw OI Data'!O15-'Raw OI Data'!P15 | R12: ='Raw OI Data'!O16-'Raw OI Data'!P16 | S12: ='Raw OI Data'!O17-'Raw OI Data'!P17 | T12: ='Raw OI Data'!O18-'Raw OI Data'!P18 | V12: ='Raw OI Data'!O19-'Raw OI Data'!P19 | W12: ='Raw OI Data'!O20-'Raw OI Data'!P20 | X12: ='Raw OI Data'!O21-'Raw OI Data'!P21 | Y12: ='Raw OI Data'!O22-'Raw OI Data'!P22
A13: LONG-SHORT RATIOS
A14: Fut Index L/S | B14: =IFERROR('Raw OI Data'!C3/'Raw OI Data'!D3,0) | C14: =IFERROR('Raw OI Data'!C4/'Raw OI Data'!D4,0) | D14: =IFERROR('Raw OI Data'!C5/'Raw OI Data'!D5,0) | E14: =IFERROR('Raw OI Data'!C6/'Raw OI Data'!D6,0) | G14: =IFERROR('Raw OI Data'!C7/'Raw OI Data'!D7,0) | H14: =IFERROR('Raw OI Data'!C8/'Raw OI Data'!D8,0) | I14: =IFERROR('Raw OI Data'!C9/'Raw OI Data'!D9,0) | J14: =IFERROR('Raw OI Data'!C10/'Raw OI Data'!D10,0) | L14: =IFERROR('Raw OI Data'!C11/'Raw OI Data'!D11,0) | M14: =IFERROR('Raw OI Data'!C12/'Raw OI Data'!D12,0) | N14: =IFERROR('Raw OI Data'!C13/'Raw OI Data'!D13,0) | O14: =IFERROR('Raw OI Data'!C14/'Raw OI Data'!D14,0) | Q14: =IFERROR('Raw OI Data'!C15/'Raw OI Data'!D15,0) | R14: =IFERROR('Raw OI Data'!C16/'Raw OI Data'!D16,0) | S14: =IFERROR('Raw OI Data'!C17/'Raw OI Data'!D17,0) | T14: =IFERROR('Raw OI Data'!C18/'Raw OI Data'!D18,0) | V14: =IFERROR('Raw OI Data'!C19/'Raw OI Data'!D19,0) | W14: =IFERROR('Raw OI Data'!C20/'Raw OI Data'!D20,0) | X14: =IFERROR('Raw OI Data'!C21/'Raw OI Data'!D21,0) | Y14: =IFERROR('Raw OI Data'!C22/'Raw OI Data'!D22,0)
A15: Fut Stock L/S | B15: =IFERROR('Raw OI Data'!E3/'Raw OI Data'!F3,0) | C15: =IFERROR('Raw OI Data'!E4/'Raw OI Data'!F4,0) | D15: =IFERROR('Raw OI Data'!E5/'Raw OI Data'!F5,0) | E15: =IFERROR('Raw OI Data'!E6/'Raw OI Data'!F6,0) | G15: =IFERROR('Raw OI Data'!E7/'Raw OI Data'!F7,0) | H15: =IFERROR('Raw OI Data'!E8/'Raw OI Data'!F8,0) | I15: =IFERROR('Raw OI Data'!E9/'Raw OI Data'!F9,0) | J15: =IFERROR('Raw OI Data'!E10/'Raw OI Data'!F10,0) | L15: =IFERROR('Raw OI Data'!E11/'Raw OI Data'!F11,0) | M15: =IFERROR('Raw OI Data'!E12/'Raw OI Data'!F12,0) | N15: =IFERROR('Raw OI Data'!E13/'Raw OI Data'!F13,0) | O15: =IFERROR('Raw OI Data'!E14/'Raw OI Data'!F14,0) | Q15: =IFERROR('Raw OI Data'!E15/'Raw OI Data'!F15,0) | R15: =IFERROR('Raw OI Data'!E16/'Raw OI Data'!F16,0) | S15: =IFERROR('Raw OI Data'!E17/'Raw OI Data'!F17,0) | T15: =IFERROR('Raw OI Data'!E18/'Raw OI Data'!F18,0) | V15: =IFERROR('Raw OI Data'!E19/'Raw OI Data'!F19,0) | W15: =IFERROR('Raw OI Data'!E20/'Raw OI Data'!F20,0) | X15: =IFERROR('Raw OI Data'!E21/'Raw OI Data'!F21,0) | Y15: =IFERROR('Raw OI Data'!E22/'Raw OI Data'!F22,0)
